<mujoco model="bluerov2">
    <compiler angle="radian" meshdir="../meshes/" />
    <size njmax="500" nconmax="100" />
    <asset>
        <mesh name="H026994 - A35 M-2 PEDESTAL ASSY - SHAREABLE" file="H026994 - A35 M-2 PEDESTAL ASSY - SHAREABLE.STL" />
        <mesh name="H024840 - A35 M-2 DRIVE MODULE, SHAREABLE" file="H024840 - A35 M-2 DRIVE MODULE, SHAREABLE.STL" />
        <mesh name="H024847 - A35 M-2 PROXIMAL TUBE ASSY - SHAREABLE" file="H024847 - A35 M-2 PROXIMAL TUBE ASSY - SHAREABLE.STL" />
        <mesh name="H024848 - A35 M-2 DISTAL TUBE ASSY - SHAREABLE" file="H024848 - A35 M-2 DISTAL TUBE ASSY - SHAREABLE.STL" />
        <mesh name="H024842 - A35 M-2 PINCER ASSY - SHAREABLE, UNDERWATER" file="H024842 - A35 M-2 PINCER ASSY - SHAREABLE, UNDERWATER.STL" />
        <mesh name="H022927 - A35 PINCER FINGER, LONG, OVERMOLD ASSY - SHAREABLE" file="H022927 - A35 PINCER FINGER, LONG, OVERMOLD ASSY - SHAREABLE.STL" />
        <mesh name="bluerov2_visual" file="bluerov2_visual.stl" />
    </asset>
    <worldbody>
        <geom type="mesh" contype="0" conaffinity="0" group="1" mesh="bluerov2_visual" />
        <geom type="mesh" mesh="bluerov2_visual" />
        <geom pos="0 0 -0.175" quat="0.000796327 1 0 0" type="mesh" mesh="H026994 - A35 M-2 PEDESTAL ASSY - SHAREABLE" />
        <geom pos="0 0 -0.175" quat="0.000796327 1 0 0" type="mesh" contype="0" conaffinity="0" group="1" rgba="0.05 0.05 0.05 1" mesh="H026994 - A35 M-2 PEDESTAL ASSY - SHAREABLE" />
        <body name="drive1_link" pos="0 -0.000132748 -0.25835" quat="0.000563088 0.707107 0.707107 -0.000563088">
            <inertial pos="0 0 0" quat="0.820473 0.339851 -0.17592 0.424708" mass="1" diaginertia="0.07 0.04 0.04" />
            <joint name="drive1_joint" pos="0 0 0" axis="0 0 1" limited="true" range="-6.28319 6.28319" damping="0.7" />
            <geom type="mesh" mesh="H024840 - A35 M-2 DRIVE MODULE, SHAREABLE" />
            <geom type="mesh" contype="0" conaffinity="0" group="1" rgba="0.05 0.05 0.05 1" mesh="H024840 - A35 M-2 DRIVE MODULE, SHAREABLE" />
            <body name="drive2_link" pos="0.07155 0 0" quat="0.707107 0 -0.707107 0">
                <inertial pos="0.17855 0 0" quat="0.18971 0.681183 0.347524 0.615814" mass="3" diaginertia="0.22376 0.207253 0.146507" />
                <joint name="drive2_joint" pos="0 0 0" axis="0 0 1" limited="true" range="-1.5708 1.5708" damping="0.7" />
                <geom quat="0 1 0 0" type="mesh" mesh="H024840 - A35 M-2 DRIVE MODULE, SHAREABLE" />
                <geom quat="0 1 0 0" type="mesh" contype="0" conaffinity="0" group="1" rgba="0.05 0.05 0.05 1" mesh="H024840 - A35 M-2 DRIVE MODULE, SHAREABLE" />
                <geom pos="0.17855 0 0" type="mesh" mesh="H024847 - A35 M-2 PROXIMAL TUBE ASSY - SHAREABLE" />
                <geom pos="0.17855 0 0" type="mesh" contype="0" conaffinity="0" group="1" rgba="0.05 0.05 0.05 1" mesh="H024847 - A35 M-2 PROXIMAL TUBE ASSY - SHAREABLE" />
                <geom pos="0.3571 0 0" quat="0 0 1 0" type="mesh" mesh="H024840 - A35 M-2 DRIVE MODULE, SHAREABLE" />
                <geom pos="0.3571 0 0" quat="0 0 1 0" type="mesh" contype="0" conaffinity="0" group="1" rgba="0.05 0.05 0.05 1" mesh="H024840 - A35 M-2 DRIVE MODULE, SHAREABLE" />
                <body name="drive3_link" pos="0.3571 0 0.07155">
                    <inertial pos="0 0 0" quat="0.540625 0.704556 -0.060003 -0.455768" mass="1" diaginertia="0.07 0.04 0.04" />
                    <joint name="drive3_joint" pos="0 0 0" axis="0 0 1" limited="true" range="-4.49 1.35" damping="0.7" />
                    <geom quat="0.5 0.5 0.5 -0.5" type="mesh" mesh="H024840 - A35 M-2 DRIVE MODULE, SHAREABLE" />
                    <geom quat="0.5 0.5 0.5 -0.5" type="mesh" contype="0" conaffinity="0" group="1" rgba="0.05 0.05 0.05 1" mesh="H024840 - A35 M-2 DRIVE MODULE, SHAREABLE" />
                    <body name="drive4_link" pos="0 0.142 0" quat="0.707107 -0.707107 0 0">
                        <inertial pos="0 0 0.064775" quat="0.270598 0.270598 0.653281 0.653281" mass="2" diaginertia="0.128392 0.1 0.0883916" />
                        <joint name="drive4_joint" pos="0 0 0" axis="0 0 1" limited="true" range="-6.28319 6.28319" damping="0.7" />
                        <geom quat="0 1 0 0" type="mesh" mesh="H024848 - A35 M-2 DISTAL TUBE ASSY - SHAREABLE" />
                        <geom quat="0 1 0 0" type="mesh" contype="0" conaffinity="0" group="1" rgba="0.05 0.05 0.05 1" mesh="H024848 - A35 M-2 DISTAL TUBE ASSY - SHAREABLE" />
                        <geom pos="0 0 0.12955" quat="-0.5 0.5 -0.5 -0.5" type="mesh" mesh="H024840 - A35 M-2 DRIVE MODULE, SHAREABLE" />
                        <geom pos="0 0 0.12955" quat="-0.5 0.5 -0.5 -0.5" type="mesh" contype="0" conaffinity="0" group="1" rgba="0.05 0.05 0.05 1" mesh="H024840 - A35 M-2 DRIVE MODULE, SHAREABLE" />
                        <body name="drive5_link" pos="0 -0.07155 0.12955" quat="-0.5 -0.5 0.5 -0.5">
                            <inertial pos="0 0 0" quat="0.820473 0.339851 -0.17592 0.424708" mass="1" diaginertia="0.07 0.04 0.04" />
                            <joint name="drive5_joint" pos="0 0 0" axis="0 0 1" limited="true" range="-6.28319 6.28319" damping="0.7" />
                            <geom quat="0 -0.707107 0 0.707107" type="mesh" mesh="H024840 - A35 M-2 DRIVE MODULE, SHAREABLE" />
                            <geom quat="0 -0.707107 0 0.707107" type="mesh" contype="0" conaffinity="0" group="1" rgba="0.05 0.05 0.05 1" mesh="H024840 - A35 M-2 DRIVE MODULE, SHAREABLE" />
                            <body name="drive6_link" pos="0.0885 0 0" quat="0.707107 0 0.707107 0">
                                <inertial pos="0 0 0" quat="0.820473 0.339851 -0.17592 0.424708" mass="1" diaginertia="0.07 0.04 0.04" />
                                <joint name="drive6_joint" pos="0 0 0" axis="0 0 1" limited="true" range="-6.28319 6.28319" damping="0.7" />
                                <geom quat="0.5 0.5 0.5 -0.5" type="mesh" mesh="H024842 - A35 M-2 PINCER ASSY - SHAREABLE, UNDERWATER" />
                                <geom quat="0.5 0.5 0.5 -0.5" type="mesh" contype="0" conaffinity="0" group="1" rgba="0.05 0.05 0.05 1" mesh="H024842 - A35 M-2 PINCER ASSY - SHAREABLE, UNDERWATER" />
                                <body name="pincer_link" pos="0.0135 0 0.0375" quat="0.5 -0.5 -0.5 -0.5">
                                    <inertial pos="0 0 0" quat="0.820473 0.339851 -0.17592 0.424708" mass="1" diaginertia="0.07 0.04 0.04" />
                                    <joint name="pincer_joint" pos="0 0 0" axis="0 0 1" limited="true" range="-0.2 0.9" damping="0.7" />
                                    <geom quat="0 1 0 0" type="mesh" mesh="H022927 - A35 PINCER FINGER, LONG, OVERMOLD ASSY - SHAREABLE" />
                                    <geom quat="0 1 0 0" type="mesh" contype="0" conaffinity="0" group="1" rgba="0.05 0.05 0.05 1" mesh="H022927 - A35 PINCER FINGER, LONG, OVERMOLD ASSY - SHAREABLE" />
                                </body>
                                <body name="pincer_link2" pos="-0.0135 0 0.0375" quat="0.5 0.5 -0.5 0.5">
                                    <inertial pos="0 0 0" quat="0.820473 0.339851 -0.17592 0.424708" mass="1" diaginertia="0.07 0.04 0.04" />
                                    <joint name="pincer_joint2" pos="0 0 0" axis="0 0 1" limited="true" range="-0.2 1" damping="0.7" />
                                    <geom quat="0 1 0 0" type="mesh" mesh="H022927 - A35 PINCER FINGER, LONG, OVERMOLD ASSY - SHAREABLE" />
                                    <geom quat="0 1 0 0" type="mesh" contype="0" conaffinity="0" group="1" rgba="0.05 0.05 0.05 1" mesh="H022927 - A35 PINCER FINGER, LONG, OVERMOLD ASSY - SHAREABLE" />
                                </body>
                            </body>
                        </body>
                    </body>
                </body>
            </body>
        </body>
    </worldbody>
</mujoco>
