<?xml version="1.0" ?>
<!-- =================================================================================== -->
<!-- |    This document was autogenerated by xacro from bluerov2_hdt.xacro             | -->
<!-- |    EDITING THIS FILE BY HAND IS NOT RECOMMENDED                                 | -->
<!-- =================================================================================== -->
<robot name="bluerov2" xmlns:xacro="http://www.ros.org/wiki/xacro">
  <mujoco>
    <compiler balanceinertia="true" discardvisual="false" fusestatic="true" meshdir="../meshes/" strippath="true"/>
  </mujoco>
  <!-- Some pretty colors -->
  <material name="blue">
    <color rgba="0.0 0.0 0.8 1.0"/>
  </material>
  <material name="green">
    <color rgba="0.0 0.8 0.0 1.0"/>
  </material>
  <material name="grey">
    <color rgba="0.7 0.7 0.7 1.0"/>
  </material>
  <material name="grey2">
    <color rgba="0.9 0.9 0.9 1.0"/>
  </material>
  <material name="red">
    <color rgba="0.8 0.0 0.0 1.0"/>
  </material>
  <material name="orange">
    <color rgba="1.0 0.5 0.0 1.0"/>
  </material>
  <material name="white">
    <color rgba="1.0 1.0 1.0 1.0"/>
  </material>
  <material name="black">
    <color rgba="0.05 0.05 0.05 1.0"/>
  </material>
  <!-- MACRO FOR THRUSTER UNITS  -->
  <!-- ROTOR DYNAMICS MACROS -->
  <!-- First order dynamics -->
  <!--
    MACROS FOR CONVERSION FUNCTIONS BETWEEN ROTOR'S ANG. VELOCITY AND
    THRUSTER FORCE
  -->
  <!-- THRUSTER MODULE MACROS  -->
  <!--
    Thruster model with first order dynamic model for the rotor dynamics
    and a proportional non-linear steady-state conversion from the rotor's
    angular velocity to output thrust force
  -->
  <!-- materials -->
  <!-- <material name="black">
        <color rgba="${200/255} ${200/255} ${200/255} 1.0"/>
    </material> -->
  <!-- <material name="grey">
        <color rgba="${64/255} ${64/255} ${64/255} 1.0"/>
    </material> -->
  <!-- <material name="yellow">
        <color rgba="${240/255} ${224/255} ${64/255} 1.0"/>
    </material> -->
  <!-- Used for fixing robot to Gazebo 'base_link' -->
  <!-- <link name="world" />

    <joint name="world_joint" type="fixed">
      <parent link="world" />
      <child link = "base_link" />
      <origin xyz="0.0 0.0 0.0" rpy="0.0 0.0 0.0" />
    </joint> -->
  <!-- segment 0 -->
  <link name="base_link"/>
  <!-- pedestal -->
  <joint name="pedestal_joint" type="fixed">
    <origin rpy="0 0 0" xyz="0 0 0"/>
    <parent link="base_link"/>
    <child link="pedestal_link"/>
  </joint>
  <link name="pedestal_link">
    <collision>
      <origin rpy="0 0 0" xyz="0 0 0"/>
      <geometry>
        <mesh filename="package://hdt_angler_description/meshes/H026994 - A35 M-2 PEDESTAL ASSY - SHAREABLE.STL"/>
      </geometry>
    </collision>
    <visual>
      <origin rpy="0 0 0" xyz="0 0 0"/>
      <geometry>
        <mesh filename="package://hdt_angler_description/meshes/H026994 - A35 M-2 PEDESTAL ASSY - SHAREABLE.STL"/>
      </geometry>
      <material name="black"/>
    </visual>
    <inertial>
      <origin rpy="0 0 0" xyz="0 0 0"/>
      <mass value="1"/>
      <inertia ixx="0.05" ixy="0.01" ixz="0.01" iyy="0.05" iyz="0.01" izz="0.05"/>
    </inertial>
  </link>
  <!-- drive 1 -->
  <joint name="drive1_joint" type="revolute">
    <axis xyz="0 0 1"/>
    <limit effort="60.0" lower="-6.28318530718" upper="6.28318530718" velocity="0.785398163397"/>
    <origin rpy="0 0 -1.57079632679" xyz="0 0 0.08335"/>
    <parent link="pedestal_link"/>
    <child link="drive1_link"/>
    <dynamics damping="0.7" friction="0.0"/>
  </joint>
  <link name="drive1_link">
    <collision>
      <origin rpy="0 0 0" xyz="0 0 0"/>
      <geometry>
        <mesh filename="package://hdt_angler_description/meshes/H024840 - A35 M-2 DRIVE MODULE, SHAREABLE.STL"/>
      </geometry>
    </collision>
    <visual>
      <origin rpy="0 0 0" xyz="0 0 0"/>
      <geometry>
        <mesh filename="package://hdt_angler_description/meshes/H024840 - A35 M-2 DRIVE MODULE, SHAREABLE.STL"/>
      </geometry>
      <material name="black"/>
    </visual>
    <inertial>
      <origin rpy="0 0 0" xyz="0 0 0"/>
      <mass value="1"/>
      <inertia ixx="0.05" ixy="0.01" ixz="0.01" iyy="0.05" iyz="0.01" izz="0.05"/>
    </inertial>
  </link>
  <!-- drive 2 -->
  <joint name="drive2_joint" type="revolute">
    <axis xyz="0 0 1"/>
    <limit effort="60.0" lower="-1.57079632679" upper="1.57079632679" velocity="0.785398163397"/>
    <origin rpy="0 -1.57079632679 0" xyz="0.07155 0 0"/>
    <parent link="drive1_link"/>
    <child link="drive2_link"/>
    <dynamics damping="0.7" friction="0.0"/>
  </joint>
  <link name="drive2_link">
    <collision>
      <origin rpy="3.14159265359 0 0" xyz="0 0 0"/>
      <geometry>
        <mesh filename="package://hdt_angler_description/meshes/H024840 - A35 M-2 DRIVE MODULE, SHAREABLE.STL"/>
      </geometry>
    </collision>
    <visual>
      <origin rpy="3.14159265359 0 0" xyz="0 0 0"/>
      <geometry>
        <mesh filename="package://hdt_angler_description/meshes/H024840 - A35 M-2 DRIVE MODULE, SHAREABLE.STL"/>
      </geometry>
      <material name="black"/>
    </visual>
    <inertial>
      <origin rpy="3.14159265359 0 0" xyz="0 0 0"/>
      <mass value="1"/>
      <inertia ixx="0.05" ixy="0.01" ixz="0.01" iyy="0.05" iyz="0.01" izz="0.05"/>
    </inertial>
  </link>
  <!-- humerus -->
  <joint name="humerus_joint" type="fixed">
    <origin rpy="0 0 0" xyz="0.17855 0 0"/>
    <parent link="drive2_link"/>
    <child link="humerus_link"/>
  </joint>
  <link name="humerus_link">
    <collision>
      <origin rpy="0 0 0" xyz="0 0 0"/>
      <geometry>
        <mesh filename="package://hdt_angler_description/meshes/H024847 - A35 M-2 PROXIMAL TUBE ASSY - SHAREABLE.STL"/>
      </geometry>
    </collision>
    <visual>
      <origin rpy="0 0 0" xyz="0 0 0"/>
      <geometry>
        <mesh filename="package://hdt_angler_description/meshes/H024847 - A35 M-2 PROXIMAL TUBE ASSY - SHAREABLE.STL"/>
      </geometry>
      <material name="black"/>
    </visual>
    <inertial>
      <origin rpy="0 0 0" xyz="0 0 0"/>
      <mass value="1"/>
      <inertia ixx="0.05" ixy="0.01" ixz="0.01" iyy="0.05" iyz="0.01" izz="0.05"/>
    </inertial>
  </link>
  <!-- elbow -->
  <joint name="elbow_joint" type="fixed">
    <origin rpy="0 0 0" xyz="0.17855 0 0"/>
    <parent link="humerus_link"/>
    <child link="elbow_link"/>
  </joint>
  <link name="elbow_link">
    <collision>
      <origin rpy="0 3.14159265359 0" xyz="0 0 0"/>
      <geometry>
        <mesh filename="package://hdt_angler_description/meshes/H024840 - A35 M-2 DRIVE MODULE, SHAREABLE.STL"/>
      </geometry>
    </collision>
    <visual>
      <origin rpy="0 3.14159265359 0" xyz="0 0 0"/>
      <geometry>
        <mesh filename="package://hdt_angler_description/meshes/H024840 - A35 M-2 DRIVE MODULE, SHAREABLE.STL"/>
      </geometry>
      <material name="black"/>
    </visual>
    <inertial>
      <origin rpy="0 3.14159265359 0" xyz="0 0 0"/>
      <mass value="1"/>
      <inertia ixx="0.05" ixy="0.01" ixz="0.01" iyy="0.05" iyz="0.01" izz="0.05"/>
    </inertial>
  </link>
  <!-- drive 3 -->
  <joint name="drive3_joint" type="revolute">
    <axis xyz="0 0 1"/>
    <!-- position limits to match parameter settings on actuator -->
    <limit effort="60.0" lower="-4.49" upper="1.35" velocity="0.785398163397"/>
    <origin rpy="0 0 0" xyz="0 0 0.07155"/>
    <parent link="elbow_link"/>
    <child link="drive3_link"/>
    <dynamics damping="0.7" friction="0.0"/>
  </joint>
  <link name="drive3_link">
    <collision>
      <origin rpy="0 1.57079632679 -1.57079632679" xyz="0 0 0"/>
      <geometry>
        <mesh filename="package://hdt_angler_description/meshes/H024840 - A35 M-2 DRIVE MODULE, SHAREABLE.STL"/>
      </geometry>
    </collision>
    <visual>
      <origin rpy="0 1.57079632679 -1.57079632679" xyz="0 0 0"/>
      <geometry>
        <mesh filename="package://hdt_angler_description/meshes/H024840 - A35 M-2 DRIVE MODULE, SHAREABLE.STL"/>
      </geometry>
      <material name="black"/>
    </visual>
    <inertial>
      <origin rpy="0 1.57079632679 -1.57079632679" xyz="0 0 0"/>
      <mass value="1"/>
      <inertia ixx="0.05" ixy="0.01" ixz="0.01" iyy="0.05" iyz="0.01" izz="0.05"/>
    </inertial>
  </link>
  <!-- drive 4 -->
  <joint name="drive4_joint" type="revolute">
    <axis xyz="0 0 1"/>
    <limit effort="60.0" lower="-6.28318530718" upper="6.28318530718" velocity="0.785398163397"/>
    <origin rpy="-1.57079632679 0 0" xyz="0 0.142 0"/>
    <parent link="drive3_link"/>
    <child link="drive4_link"/>
    <dynamics damping="0.7" friction="0.0"/>
  </joint>
  <link name="drive4_link">
    <collision>
      <origin rpy="3.14159265359 0 0" xyz="0 0 0"/>
      <geometry>
        <mesh filename="package://hdt_angler_description/meshes/H024848 - A35 M-2 DISTAL TUBE ASSY - SHAREABLE.STL"/>
      </geometry>
    </collision>
    <visual>
      <origin rpy="3.14159265359 0 0" xyz="0 0 0"/>
      <geometry>
        <mesh filename="package://hdt_angler_description/meshes/H024848 - A35 M-2 DISTAL TUBE ASSY - SHAREABLE.STL"/>
      </geometry>
      <material name="black"/>
    </visual>
    <inertial>
      <origin rpy="3.14159265359 0 0" xyz="0 0 0"/>
      <mass value="1"/>
      <inertia ixx="0.05" ixy="0.01" ixz="0.01" iyy="0.05" iyz="0.01" izz="0.05"/>
    </inertial>
  </link>
  <!-- wrist -->
  <joint name="wrist_joint" type="fixed">
    <origin rpy="1.57079632679 -1.57079632679 3.14159265359" xyz="0 0 0.12955"/>
    <parent link="drive4_link"/>
    <child link="wrist_link"/>
  </joint>
  <link name="wrist_link">
    <collision>
      <origin rpy="0 0 3.14159265359" xyz="0 0 0"/>
      <geometry>
        <mesh filename="package://hdt_angler_description/meshes/H024840 - A35 M-2 DRIVE MODULE, SHAREABLE.STL"/>
      </geometry>
    </collision>
    <visual>
      <origin rpy="0 0 3.14159265359" xyz="0 0 0"/>
      <geometry>
        <mesh filename="package://hdt_angler_description/meshes/H024840 - A35 M-2 DRIVE MODULE, SHAREABLE.STL"/>
      </geometry>
      <material name="black"/>
    </visual>
    <inertial>
      <origin rpy="0 0 3.14159265359" xyz="0 0 0"/>
      <mass value="1"/>
      <inertia ixx="0.05" ixy="0.01" ixz="0.01" iyy="0.05" iyz="0.01" izz="0.05"/>
    </inertial>
  </link>
  <!-- drive 5 -->
  <joint name="drive5_joint" type="revolute">
    <axis xyz="0 0 1"/>
    <limit effort="60.0" lower="-6.28318530718" upper="6.28318530718" velocity="0.785398163397"/>
    <origin rpy="3.14159265359 0 0" xyz="0 0 -0.07155"/>
    <parent link="wrist_link"/>
    <child link="drive5_link"/>
    <dynamics damping="0.7" friction="0.0"/>
  </joint>
  <link name="drive5_link">
    <collision>
      <origin rpy="0 1.57079632679 3.14159265359" xyz="0 0 0"/>
      <geometry>
        <mesh filename="package://hdt_angler_description/meshes/H024840 - A35 M-2 DRIVE MODULE, SHAREABLE.STL"/>
      </geometry>
    </collision>
    <visual>
      <origin rpy="0 1.57079632679 3.14159265359" xyz="0 0 0"/>
      <geometry>
        <mesh filename="package://hdt_angler_description/meshes/H024840 - A35 M-2 DRIVE MODULE, SHAREABLE.STL"/>
      </geometry>
      <material name="black"/>
    </visual>
    <inertial>
      <origin rpy="0 0 0" xyz="0 0 0"/>
      <mass value="1"/>
      <inertia ixx="0.05" ixy="0.01" ixz="0.01" iyy="0.05" iyz="0.01" izz="0.05"/>
    </inertial>
  </link>
  <!-- drive 6 -->
  <joint name="drive6_joint" type="revolute">
    <axis xyz="0 0 1"/>
    <limit effort="60.0" lower="-6.28318530718" upper="6.28318530718" velocity="0.785398163397"/>
    <origin rpy="0 1.57079632679 0" xyz="0.0885 0 0"/>
    <parent link="drive5_link"/>
    <child link="drive6_link"/>
    <dynamics damping="0.7" friction="0.0"/>
  </joint>
  <link name="drive6_link">
    <collision>
      <origin rpy="0 1.57079632679 -1.57079632679" xyz="0 0 0"/>
      <geometry>
        <mesh filename="package://hdt_angler_description/meshes/H024842 - A35 M-2 PINCER ASSY - SHAREABLE, UNDERWATER.STL"/>
      </geometry>
    </collision>
    <visual>
      <origin rpy="0 1.57079632679 -1.57079632679" xyz="0 0 0"/>
      <geometry>
        <mesh filename="package://hdt_angler_description/meshes/H024842 - A35 M-2 PINCER ASSY - SHAREABLE, UNDERWATER.STL"/>
      </geometry>
      <material name="black"/>
    </visual>
    <inertial>
      <origin rpy="0 0 0" xyz="0 0 0"/>
      <mass value="1"/>
      <inertia ixx="0.05" ixy="0.01" ixz="0.01" iyy="0.05" iyz="0.01" izz="0.05"/>
    </inertial>
  </link>
  <!-- Pincers -->
  <joint name="pincer_joint" type="revolute">
    <hdt id="10" inertia="0.075" kmax="150" kmin="75"/>
    <axis xyz="0 0 1"/>
    <limit effort="60.0" lower="-0.2" upper="0.9" velocity="0.5"/>
    <origin rpy="-1.57079632679 -1.57079632679 0" xyz="0.0135 0 0.0375"/>
    <parent link="drive6_link"/>
    <child link="pincer_link"/>
    <dynamics damping="0.7" friction="0.0"/>
  </joint>
  <link name="pincer_link">
    <collision>
      <origin rpy="3.14159265359 0 0" xyz="0 0 0"/>
      <geometry>
        <mesh filename="package://hdt_angler_description/meshes/H022927 - A35 PINCER FINGER, LONG, OVERMOLD ASSY - SHAREABLE.STL"/>
      </geometry>
    </collision>
    <visual>
      <origin rpy="3.14159265359 0 0" xyz="0 0 0"/>
      <geometry>
        <mesh filename="package://hdt_angler_description/meshes/H022927 - A35 PINCER FINGER, LONG, OVERMOLD ASSY - SHAREABLE.STL"/>
      </geometry>
      <material name="black"/>
    </visual>
    <inertial>
      <origin rpy="0 0 0" xyz="0 0 0"/>
      <mass value="1"/>
      <inertia ixx="0.05" ixy="0.01" ixz="0.01" iyy="0.05" iyz="0.01" izz="0.05"/>
    </inertial>
  </link>
  <!-- EE 2 -->
  <!-- THIS IS THE SECOND PINCER, NEEDS TO MOVE EQUAL BUT OPPOSITE AS PINCER 1 -->
  <joint name="pincer_joint2" type="revolute">
    <!--<hdt id="10b" kmin="75" kmax="150" inertia="0.075"/>-->
    <axis xyz="0 0 1"/>
    <origin rpy="-1.57079632679 -1.57079632679 3.14159265359" xyz="-0.0135 0 0.0375"/>
    <parent link="drive6_link"/>
    <child link="pincer_link2"/>
    <calibration rising="0.0"/>
    <dynamics damping="0.7" friction="0.0"/>
    <limit effort="60.0" lower="-0.2" upper="1" velocity="0.5"/>
    <mimic joint="pincer_joint" multiplier="1" offset="0.0"/>
  </joint>
  <link name="pincer_link2">
    <collision>
      <origin rpy="3.14159265359 0 0" xyz="0 0 0"/>
      <geometry>
        <mesh filename="package://hdt_angler_description/meshes/H022927 - A35 PINCER FINGER, LONG, OVERMOLD ASSY - SHAREABLE.STL"/>
      </geometry>
    </collision>
    <visual>
      <origin rpy="3.14159265359 0 0" xyz="0 0 0"/>
      <geometry>
        <mesh filename="package://hdt_angler_description/meshes/H022927 - A35 PINCER FINGER, LONG, OVERMOLD ASSY - SHAREABLE.STL"/>
      </geometry>
      <material name="black"/>
    </visual>
    <inertial>
      <origin rpy="0 0 0" xyz="0 0 0"/>
      <mass value="1"/>
      <inertia ixx="0.05" ixy="0.01" ixz="0.01" iyy="0.05" iyz="0.01" izz="0.05"/>
    </inertial>
  </link>
  <!-- endpoint -->
  <joint name="endpoint_joint" type="fixed">
    <origin rpy="1.57079632679 -1.57079632679 0" xyz="0 0 0.1"/>
    <parent link="drive6_link"/>
    <child link="endpoint_link"/>
  </joint>
  <link name="endpoint_link">
    </link>
  <joint name="rov_arm_joint" type="fixed">
    <parent link="bluerov2/base_link"/>
    <child link="base_link"/>
    <origin rpy="3.14 0 0" xyz="0. 0. -0.175"/>
  </joint>
  <!-- Used for fixing robot to Gazebo 'base_link' -->
  <!-- <link name="world" />

  <joint name="world_joint" type="fixed">
    <parent link="world" />
    <child link = "base_link" />
    <origin xyz="0.0 0.0 0.0" rpy="0.0 0.0 0.0" />
  </joint> -->
  <!-- Rigid body description of the base link -->
  <link name="bluerov2/base_link">
    <!--
          Be careful to setup the coefficients for the inertial tensor,
          otherwise your model will become unstable on Gazebo
        -->
    <inertial>
      <mass value="10"/>
      <origin rpy="0 0 0" xyz="0 0 0"/>
      <!-- <inertia ixx="525.39" ixy="1.44" ixz="33.41" iyy="794.20" iyz="2.6" izz="691.23"/> -->
      <inertia ixx="0.2712091912" ixy="0.0" ixz="0.0" iyy="0.5589480712" iyz="0.0" izz="0.51507712"/>
    </inertial>
    <!-- This visual geometry representation can be used when running
             tasks in which you need Gazebo to start quickly
        -->
    <!-- <xacro:if value="${use_simplified_mesh}"> -->
    <!-- Code in rexrov2_base.xacro if use the flag use_simplified_mesh -->
    <visual>
      <origin rpy="0 0 0" xyz="0 0 0"/>
      <geometry>
        <mesh filename="file:///home/cong/ros_ws/hdt_new_ws/src/bluerov2/bluerov2_description/meshes/bluerov2_visual.stl" scale="1 1 1"/>
      </geometry>
    </visual>
    <!-- In rexrov2_base they made collision planes to minize the GPU load -->
    <collision>
      <origin rpy="0 0 0" xyz="0 0 0"/>
      <geometry>
        <mesh filename="file:///home/cong/ros_ws/hdt_new_ws/src/bluerov2/bluerov2_description/meshes/bluerov2_visual.stl" scale="1 1 1"/>
      </geometry>
    </collision>
  </link>
  <gazebo reference="bluerov2/base_link">
    <selfCollide>false</selfCollide>
  </gazebo>
  <!-- Set up hydrodynamic plugin given as input parameter -->
  <gazebo>
    <plugin filename="libunderwater_object_ros_plugin.so" name="uuv_plugin">
      <fluid_density>1028.0</fluid_density>
      <flow_velocity_topic>hydrodynamics/current_velocity</flow_velocity_topic>
      <debug>0</debug>
      <!-- List of hydrodynamic models this robot's links -->
      <link name="bluerov2/base_link">
        <!-- This flag will make the link neutrally buoyant -->
        <neutrally_buoyant>0</neutrally_buoyant>
        <!-- Link's volume -->
        <volume>0.011054</volume>
        <!-- Link's bounding box, it is used to recalculate the immersed
        volume when close to the surface.
        This is a workaround the invalid bounding box given by Gazebo-->
        <box>
          <width>0.448</width>
          <length>0.2384</length>
          <height>0.28066</height>
        </box>
        <!-- Center of buoyancy -->
        <center_of_buoyancy>0 0 0</center_of_buoyancy>
        <!-- Fossen's equation of motion for underwater vehicles
      Reference:
          [1] Fossen, Thor I. Handbook of marine craft hydrodynamics and motion
          control. John Wiley & Sons, 2011.
     -->
        <hydrodynamic_model>
          <type>fossen</type>
          <!-- Added mass: see p.28 in Berg2012 -->
          <added_mass>
            1.7182 0 0 0 0 0
            0 0 0 0 0 0
            0 0 5.468 0 0 0
            0 0 0 0 0 0
            0 0 0 0 1.2481 0
            0 0 0 0 0 0.4006
          </added_mass>
          <!--
            The linear damping coefficients can be provided as a diagonal (6 elements)
            or a full matrix (36 coefficients), like the added-mass coefficients above
            Linear damping: see p.31 in Berg2012
          -->
          <linear_damping>
            -11.7391 -20 -31.8678 -25 -44.9085 -5
          </linear_damping>
          <!--
            The linear damping coefficients proportional to the forward speed
            can be provided as a diagonal (6 elements) or a full matrix (36 coefficients),
            like the added-mass coefficients above.
            This matrix is mostly useful for slender bodies (e.g. AUVs with torpedo shape)
          -->
          <!-- <linear_damping_forward_speed>
            0 0 0 0 0 0
          </linear_damping_forward_speed> -->
          <!--
            The quadratic damping coefficients can be provided as a diagonal (6 elements)
            or a full matrix (36 coefficients), like the added-mass coefficients above
            Non-linear damping: see p.30 in Berg2012
          -->
          <quadratic_damping>
            0 0 0 0 0 0
          </quadratic_damping>
          <!--
            In case you want to model a simple surface vessel, you can use the
            implementation of linear (small angle) theory for boxed shaped vessels
            by providing the following parameters. If you omit the area of the
            water level plane area, it will be calculated from the bounding box
            parameters. Uncomment the lines below in case you are simulating a
            surface vessel.
            For more details on these parameters and the computation of buoyancy
            for vessels using this theory, check:
              [1] Lecture Notes  TTK 4190 Guidance and Control of Vehicles (T. I. Fossen)
                  http://www.fossen.biz/wiley/Ch4.pdf
              [2] Fossen, Thor I. Handbook of marine craft hydrodynamics and motion
                  control. John Wiley & Sons, 2011.
          -->
          <!--
          <metacentric_width>0.0</metacentric_width>
          <metacentric_length>0.0</metacentric_length>
          <water_level_plane_area>0.0</water_level_plane_area>
          -->
        </hydrodynamic_model>
      </link>
      <!--
          In case other modules are added to the vehicle (such as a manipulator)
          that also have link running with the underwater object plugin, they
          should also be added in this block. For this, this new module should
          have a file similar to gazebo.xacro above with the description of the
          parameter necessary for the underwater object plugin to be initialized.
        -->
    </plugin>
  </gazebo>
 
</robot>

